Workbook

Sheet Summary
B2: Coverage
B4: Companies Covered | C4: =COUNTA(CCA_Defense!C3:C1048576) -> 84

Sheet CCA_Defense
D1: Ticker | M1: P/E | T1: Derived | U1: Mgmt Input | AH1: Platforms | AK1: Tier 1 | AN1: Tier 2 | AP1: Tier 3 | AS1: Tier 4 | AU1: . | AV1: Shares Outstanding (# Mn) | AY1: Revenue ($ Mn) | BC1: EV/EBITDA (x) | BG1: ROE (%) | BK1: ROCE (%) | BO1: Net Debt / EBITDA | BS1: Debt-Equity Ratio | BV1: PAT (%) | BY1: FCFF (Yield on EV) | CB1: Working Capital Cycle | CE1: . | CF1: Performance
B2: # | C2: Company | D2: BB | E2: Exch | F2: Mkt cap $mm | G2: Incorporation Date | H2: Legacy | I2: Type/status | J2: Sub-Segment | K2: TAM CAGR (FY30) | L2: Management Meeting | M2: Current | N2: FY26P | O2: FY27P | P2: FY28P | Q2: FY29P | R2: FY30P | S2: T12 rev YoY (%) | T2: CAGR (5-Yr) (%) | V2: Def. rev% | W2: Orderbook Visibility (x) | X2: Type | Y2: Location | Z2: Promoter | AA2: Prom. own% | AB2: Other s'holders | AC2: Barriers to Entry | AD2: Switching Costs | AE2: Customer Stickiness | AF2: Insights from Mgmt | AG2: Comments | AH2: Aerospace Systems | AI2: Land Systems\ | AJ2: Naval Systems | AK2: Mechanical Systems | AL2: Structural Systems | AM2: Weapon Systems | AN2: Munitions & Ordnance | AO2: Other Stand-Alone Items | AP2: Electrical Equipment & Components | AQ2: Electronic Equipment & Components | AR2: Test Solutions & Engineering | AS2: Raw Materials | AT2: Precision Components | AU2: Value Chain | AV2: FY25 | AW2: FY24 | AX2: FY23 | AY2: FY25E | AZ2: FY24 | BA2: FY23 | BB2: FY22 | BC2: FY25 | BD2: FY24 | BE2: FY23 | BF2: FY22 | BG2: FY25 | BH2: FY24 | BI2: FY23 | BJ2: FY22 | BK2: FY25 | BL2: FY24 | BM2: FY23 | BN2: FY22 | BO2: FY25 | BP2: FY24 | BQ2: FY23 | BR2: FY22 | BS2: FY24 | BT2: FY23 | BU2: FY22 | BV2: FY25 | BW2: FY24 | BX2: FY23 | BY2: FY25 | BZ2: FY24 | CA2: FY23 | CB2: FY25 | CC2: FY24 | CD2: FY23 | CE2: Rev CAGR (4-Yr) | CF2: CAGR (%) | CG2: PE (X) | CH2: ROE (%) | CI2: ROCE (%) | CJ2: Total Score | CK2: BBrow
B3: 1 | C3: Hindustan Aeronautics Limited | D3: HNAL | E3: HAL | F3: =_xlfn.XLOOKUP(CCA_Defense!$D3,BB_Input!$C$4:$C$172,BB_Input!$G$4:$G$172) -> 32941.531 | G3: 1940 | H3: =YEAR(TODAY())-G3 -> 86 | I3: Listed | J3: Aircraft OEM | K3: 0.07 | M3: 39.65 | N3: =IFERROR(_xlfn.XLOOKUP($D3,PE_Projections!$D:$D,PE_Projections!L:L),"") -> 34.750906 | O3: =IFERROR(_xlfn.XLOOKUP($D3,PE_Projections!$D:$D,PE_Projections!M:M),"") -> 29.185423 | P3: =IFERROR(_xlfn.XLOOKUP($D3,PE_Projections!$D:$D,PE_Projections!N:N),"") -> 25.131017 | Q3: =IFERROR(_xlfn.XLOOKUP($D3,PE_Projections!$D:$D,PE_Projections!O:O),"") -> 21.546295 | R3: =IFERROR(_xlfn.XLOOKUP($D3,PE_Projections!$D:$D,PE_Projections!P:P),"") | S3: 79.36 | T3: =IFERROR(RATE(5,,BB3,-AY3),"") -> 0.073652201 | V3: =AVERAGE(0.6,0.7) -> 0.65 | W3: 7.6 | X3: {=_xlfn.IFS($F3<Glossary!$C$54,Glossary!$B$54,$F3<Glossary!$C$55,Glossary!$B$55,$F3>Glossary!$C$56,Glossary!$B$56)} -> Large Cap | Y3: Bangalore | Z3: Government | AA3: 0.7164 | AC3: High | AD3: High | AE3: High | AH3: Y | AM3: Y | AQ3: Y | AT3: Y | AU3: Diversified | AV3: 3344 | AW3: 3344 | AX3: 3344 | AY3: 3929 | AZ3: 3490 | BA3: 3135 | BB3: 2754 | BC3: 24.2 | BD3: 4.7 | BE3: 6.8 | BG3: 0.267 | BH3: 0.289 | BI3: 0.2717 | BJ3: 0.2955 | BK3: 0.338 | BL3: 0.35 | BM3: 0.28 | BN3: 0.27 | BO3: 0 | BP3: 0 | BQ3: 0 | BR3: 0 | BS3: 0 | BT3: 0 | BU3: 0 | CE3: =IFERROR(RATE(4,,BB3,-AY3),"") -> 0.092897728 | CF3: =IF(CE3>='Conviction List'!$D$4,1,"") | CG3: =IF(M1<='Conviction List'!$E$4,1,"") | CH3: =IF(BG3>='Conviction List'!$F$4,1,"") -> 1 | CI3: =IF(BK3>='Conviction List'!$G$4,1,"") -> 1 | CJ3: =SUM(CF3:CI3) -> 2 | CK3: =MATCH($D3,INDIRECT($C$90&"!$C$1:$C$164"),0) -> 5
B4: =B3+1 -> 2 | C4: Bharat Electronics Limited | D4: BHE | E4: BEL | F4: =_xlfn.XLOOKUP(CCA_Defense!$D4,BB_Input!$C$4:$C$172,BB_Input!$G$4:$G$172) -> 32574.519 | G4: 1954 | H4: =YEAR(TODAY())-G4 -> 72 | I4: Listed | J4: Radars/Comms | K4: 0.0618 | M4: 61.39 | N4: =IFERROR(_xlfn.XLOOKUP($D4,PE_Projections!$D:$D,PE_Projections!L:L),"") -> 48.548221 | O4: =IFERROR(_xlfn.XLOOKUP($D4,PE_Projections!$D:$D,PE_Projections!M:M),"") -> 40.935212 | P4: =IFERROR(_xlfn.XLOOKUP($D4,PE_Projections!$D:$D,PE_Projections!N:N),"") -> 34.951751 | Q4: =IFERROR(_xlfn.XLOOKUP($D4,PE_Projections!$D:$D,PE_Projections!O:O),"") -> 31.397174 | R4: =IFERROR(_xlfn.XLOOKUP($D4,PE_Projections!$D:$D,PE_Projections!P:P),"") | S4: 172.03 | T4: =IFERROR(RATE(5,,BB4,-AY4),"") -> 0.069230988 | V4: 0.92 | W4: 3.6 | X4: {=_xlfn.IFS($F4<Glossary!$C$54,Glossary!$B$54,$F4<Glossary!$C$55,Glossary!$B$55,$F4>Glossary!$C$56,Glossary!$B$56)} -> Large Cap | Y4: Bangalore | Z4: Government | AA4: 0.5114 | AC4: High | AD4: High | AE4: High | AH4: Y | AQ4: Y | AU4: Diversified | AV4: 7280 | AW4: 7280 | AX4: 7280 | AY4: 2591 | AZ4: 2318 | BA4: 2144 | BB4: 1854 | BC4: 40.06 | BD4: 8 | BE4: 9.5 | BG4: 0.2932 | BH4: 0.18 | BI4: 0.165 | BJ4: 0.15 | BK4: 0.3899 | BL4: 0.2 | BM4: 0.18 | BN4: 0.165 | BO4: 0 | BP4: 0 | BQ4: 0 | BR4: 0 | BS4: 0 | BT4: 0 | BU4: 0 | CE4: =IFERROR(RATE(4,,BB4,-AY4),"") -> 0.087275046 | CF4: =IF(CE4>='Conviction List'!$D$4,1,"") | CG4: =IF(M2<='Conviction List'!$E$4,1,"") | CH4: =IF(BG4>='Conviction List'!$F$4,1,"") -> 1 | CI4: =IF(BK4>='Conviction List'!$G$4,1,"") -> 1 | CJ4: =SUM(CF4:CI4) -> 2 | CK4: =MATCH($D4,INDIRECT($C$90&"!$C$1:$C$164"),0) -> 6
B5: =B4+1 -> 3 | C5: Bharat Dynamics Limited | D5: BDL | E5: BDL | F5: =_xlfn.XLOOKUP(CCA_Defense!$D5,BB_Input!$C$4:$C$172,BB_Input!$G$4:$G$172) -> 6048.8875 | G5: 1970 | H5: =YEAR(TODAY())-G5 -> 56 | I5: Listed | J5: Missiles | M5: 61.75 | N5: =IFERROR(_xlfn.XLOOKUP($D5,PE_Projections!$D:$D,PE_Projections!L:L),"") -> 58.607226 | O5: =IFERROR(_xlfn.XLOOKUP($D5,PE_Projections!$D:$D,PE_Projections!M:M),"") -> 44.206127 | P5: =IFERROR(_xlfn.XLOOKUP($D5,PE_Projections!$D:$D,PE_Projections!N:N),"") -> 34.064669 | Q5: =IFERROR(_xlfn.XLOOKUP($D5,PE_Projections!$D:$D,PE_Projections!O:O),"") -> 39.967619 | R5: =IFERROR(_xlfn.XLOOKUP($D5,PE_Projections!$D:$D,PE_Projections!P:P),"") | S5: 98.4 | T5: =IFERROR(RATE(5,,BB5,-AY5),"") -> 0.062356498 | V5: 1 | W5: 3.54 | X5: {=_xlfn.IFS($F5<Glossary!$C$54,Glossary!$B$54,$F5<Glossary!$C$55,Glossary!$B$55,$F5>Glossary!$C$56,Glossary!$B$56)} -> Mid Cap | Y5: Hyderabad | Z5: Government | AA5: 0.7493 | AC5: High | AD5: High | AE5: High | AM5: Y | AU5: Tier 1 | AV5: 183.3 | AW5: 183.3 | AX5: 183.3 | AY5: 705 | AZ5: 638 | BA5: 579 | BB5: 521 | BC5: 83.5 | BD5: 10.2 | BE5: 11 | BG5: 0.1438 | BH5: 0.15 | BI5: 0.14 | BJ5: 0.125 | BK5: 0.1965 | BL5: 0.155 | BM5: 0.14 | BN5: 0.125 | BO5: 0 | BP5: 0 | BQ5: 0 | BR5: 0 | BS5: 0 | BT5: 0 | BU5: 0 | CE5: =IFERROR(RATE(4,,BB5,-AY5),"") -> 0.078543953 | CF5: =IF(CE5>='Conviction List'!$D$6,1,"") -> 1 | CG5: =IF(M5<='Conviction List'!$E$6,1,"") -> 1 | CH5: =IF(BG5>='Conviction List'!$F$6,1,"") -> 1 | CI5: =IF(BK5>='Conviction List'!$G$6,1,"") -> 1 | CJ5: =SUM(CF5:CI5) -> 4 | CK5: =MATCH($D5,INDIRECT($C$90&"!$C$1:$C$164"),0) -> 7
B6: =B5+1 -> 4 | C6: Mazagon Dock Shipbuilders Limited | D6: MAZDOCKS | E6: MAZDOCK | F6: =_xlfn.XLOOKUP(CCA_Defense!$D6,BB_Input!$C$4:$C$172,BB_Input!$G$4:$G$172) -> 11415.979 | G6: 1934 | H6: =YEAR(TODAY())-G6 -> 92 | I6: Listed | J6: Warships | M6: 38.06 | N6: =IFERROR(_xlfn.XLOOKUP($D6,PE_Projections!$D:$D,PE_Projections!L:L),"") -> 37.053118 | O6: =IFERROR(_xlfn.XLOOKUP($D6,PE_Projections!$D:$D,PE_Projections!M:M),"") -> 30.396666 | P6: =IFERROR(_xlfn.XLOOKUP($D6,PE_Projections!$D:$D,PE_Projections!N:N),"") -> 28.26324 | Q6: =IFERROR(_xlfn.XLOOKUP($D6,PE_Projections!$D:$D,PE_Projections!O:O),"") | R6: =IFERROR(_xlfn.XLOOKUP($D6,PE_Projections!$D:$D,PE_Projections!P:P),"") | S6: 75.76 | T6: =IFERROR(RATE(5,,BB6,-AY6),"") -> 0.047036671 | V6: 1 | W6: 5.7 | X6: {=_xlfn.IFS($F6<Glossary!$C$54,Glossary!$B$54,$F6<Glossary!$C$55,Glossary!$B$55,$F6>Glossary!$C$56,Glossary!$B$56)} -> Large Cap | Y6: Mumbai | Z6: Government | AA6: 0.8483 | AC6: High | AD6: High | AE6: High | AJ6: Y | AU6: Platforms | AV6: 201.7 | AW6: 201.7 | AX6: 201.7 | AY6: 526 | AZ6: 487 | BA6: 441 | BB6: 418 | BC6: 37.13 | BD6: 9.5 | BE6: 10 | BH6: 0.102 | BI6: 0.098 | BJ6: 0.085 | BL6: 0.12 | BM6: 0.115 | BN6: 0.1 | BO6: 0 | BP6: 0 | BQ6: 0 | BR6: 0 | BS6: 0 | BT6: 0 | BU6: 0 | CE6: =IFERROR(RATE(4,,BB6,-AY6),"") -> 0.05913755 | CF6: =IF(CE6>='Conviction List'!$D$5,1,"") | CG6: =IF(M6<='Conviction List'!$E$5,1,"") -> 1 | CH6: =IF(BG6>='Conviction List'!$F$5,1,"") | CI6: =IF(BK6>='Conviction List'!$G$5,1,"") | CJ6: =SUM(CF6:CI6) -> 1 | CK6: =MATCH($D6,INDIRECT($C$90&"!$C$1:$C$164"),0) -> 8
B7: =B6+1 -> 5 | C7: Garden Reach Shipbuilders & Engineers | D7: GRSE | E7: GRSE | F7: =_xlfn.XLOOKUP(CCA_Defense!$D7,BB_Input!$C$4:$C$172,BB_Input!$G$4:$G$172) -> 3131.5232 | G7: 1934 | H7: =YEAR(TODAY())-G7 -> 92 | I7: Listed | J7: Warships | M7: 88.75 | N7: =IFERROR(_xlfn.XLOOKUP($D7,PE_Projections!$D:$D,PE_Projections!L:L),"") -> 38.480116 | O7: =IFERROR(_xlfn.XLOOKUP($D7,PE_Projections!$D:$D,PE_Projections!M:M),"") -> 28.728985 | P7: =IFERROR(_xlfn.XLOOKUP($D7,PE_Projections!$D:$D,PE_Projections!N:N),"") -> 26.557715 | Q7: =IFERROR(_xlfn.XLOOKUP($D7,PE_Projections!$D:$D,PE_Projections!O:O),"") | R7: =IFERROR(_xlfn.XLOOKUP($D7,PE_Projections!$D:$D,PE_Projections!P:P),"") | S7: 225.73 | T7: =IFERROR(RATE(5,,BB7,-AY7),"") -> 0.043826858 | V7: 1 | W7: 4 | X7: {=_xlfn.IFS($F7<Glossary!$C$54,Glossary!$B$54,$F7<Glossary!$C$55,Glossary!$B$55,$F7>Glossary!$C$56,Glossary!$B$56)} -> Mid Cap | Y7: Kolkata | Z7: Government | AA7: 0.745 | AC7: High | AD7: High | AE7: High | AJ7: Y | AU7: Platforms | AV7: 114.6 | AW7: 114.6 | AX7: 114.6 | AY7: 373 | AZ7: 348 | BA7: 324 | BB7: 301 | BC7: 40.3 | BG7: 0.2811 | BH7: 0.12 | BI7: 0.115 | BJ7: 0.1 | BK7: 0.3728 | BL7: 0.125 | BM7: 0.11 | BN7: 0.105 | BO7: 3.5 | BP7: 3.4 | BQ7: 3.2 | BR7: 3 | BS7: 0.005 | BT7: 0.007 | BU7: 0.008 | CE7: =IFERROR(RATE(4,,BB7,-AY7),"") -> 0.05508047 | CF7: =IF(CE7>='Conviction List'!$D$5,1,"") | CG7: =IF(M7<='Conviction List'!$E$5,1,"") | CH7: =IF(BG7>='Conviction List'!$F$5,1,"") -> 1 | CI7: =IF(BK7>='Conviction List'!$G$5,1,"") -> 1 | CJ7: =SUM(CF7:CI7) -> 2 | CK7: =MATCH($D7,INDIRECT($C$90&"!$C$1:$C$164"),0) -> 9
B8: =B7+1 -> 6 | C8: Cochin Shipyard Limited | D8: COCHIN | E8: COCHINSHIP | F8: =_xlfn.XLOOKUP(CCA_Defense!$D8,BB_Input!$C$4:$C$172,BB_Input!$G$4:$G$172) -> 4833.9547 | G8: 1972 | H8: =YEAR(TODAY())-G8 -> 54 | I8: Listed | J8: Shipbuilding | M8: 48.8 | N8: =IFERROR(_xlfn.XLOOKUP($D8,PE_Projections!$D:$D,PE_Projections!L:L),"") -> 59.974547 | O8: =IFERROR(_xlfn.XLOOKUP($D8,PE_Projections!$D:$D,PE_Projections!M:M),"") -> 45.560775 | P8: =IFERROR(_xlfn.XLOOKUP($D8,PE_Projections!$D:$D,PE_Projections!N:N),"") -> 37.626617 | Q8: =IFERROR(_xlfn.XLOOKUP($D8,PE_Projections!$D:$D,PE_Projections!O:O),"") | R8: =IFERROR(_xlfn.XLOOKUP($D8,PE_Projections!$D:$D,PE_Projections!P:P),"") | S8: 156.7 | T8: =IFERROR(RATE(5,,BB8,-AY8),"") -> 0.15561324 | V8: =AVERAGE(0.6,0.7) -> 0.65 | W8: 5 | X8: {=_xlfn.IFS($F8<Glossary!$C$54,Glossary!$B$54,$F8<Glossary!$C$55,Glossary!$B$55,$F8>Glossary!$C$56,Glossary!$B$56)} -> Mid Cap | Y8: Cochin | Z8: Government | AA8: 0.6791 | AC8: High | AD8: High | AE8: High | AJ8: Y | AU8: Platforms | AV8: 131.6 | AW8: 131.6 | AX8: 131.6 | AY8: 5649 | AZ8: 4439 | BA8: 3698 | BB8: 2741 | BC8: 41.04 | BD8: 36.9 | BE8: 47.3 | BH8: 0.16 | BI8: 0.13 | BJ8: 0.06 | BL8: 0.22 | BM8: 0.2 | BN8: 0.09 | BO8: 3 | BP8: 2.8 | BQ8: 2.5 | BR8: 2.1 | BS8: 1.18 | BT8: 2.1 | BU8: 3.46 | CE8: =IFERROR(RATE(4,,BB8,-AY8),"") -> 0.19816226 | CF8: =IF(CE8>='Conviction List'!$D$5,1,"") -> 1 | CG8: =IF(M8<='Conviction List'!$E$5,1,"") | CH8: =IF(BG8>='Conviction List'!$F$5,1,"") | CI8: =IF(BK8>='Conviction List'!$G$5,1,"") | CJ8: =SUM(CF8:CI8) -> 1 | CK8: =MATCH($D8,INDIRECT($C$90&"!$C$1:$C$164"),0) -> 10
B9: =B8+1 -> 7 | C9: BEML Limited | D9: BEML | E9: BEML | F9: =_xlfn.XLOOKUP(CCA_Defense!$D9,BB_Input!$C$4:$C$172,BB_Input!$G$4:$G$172) -> 1733.2255 | G9: 1964 | H9: =YEAR(TODAY())-G9 -> 62 | I9: Listed | J9: Military vehicles | M9: 59.41 | N9: =IFERROR(_xlfn.XLOOKUP($D9,PE_Projections!$D:$D,PE_Projections!L:L),"") -> 38.8041 | O9: =IFERROR(_xlfn.XLOOKUP($D9,PE_Projections!$D:$D,PE_Projections!M:M),"") -> 27.780973 | P9: =IFERROR(_xlfn.XLOOKUP($D9,PE_Projections!$D:$D,PE_Projections!N:N),"") -> 22.834964 | Q9: =IFERROR(_xlfn.XLOOKUP($D9,PE_Projections!$D:$D,PE_Projections!O:O),"") | R9: =IFERROR(_xlfn.XLOOKUP($D9,PE_Projections!$D:$D,PE_Projections!P:P),"") | S9: 49.9 | T9: =IFERROR(RATE(5,,BB9,-AY9),"") -> 0.051918152 | V9: =AVERAGE(0.45,0.5) -> 0.475 | W9: 3.4 | X9: {=_xlfn.IFS($F9<Glossary!$C$54,Glossary!$B$54,$F9<Glossary!$C$55,Glossary!$B$55,$F9>Glossary!$C$56,Glossary!$B$56)} -> Small Cap | Y9: Bangalore | Z9: Government | AA9: 0.5403 | AC9: Medium | AD9: High | AE9: Medium | AH9: Y | AI9: Y | AT9: Y | AU9: Diversified | AV9: 41.7 | AW9: 41.7 | AX9: 41.7 | AY9: 568 | AZ9: 522 | BA9: 487 | BB9: 441 | BC9: 36.1 | BD9: 11.5 | BE9: 12 | BH9: 0.14 | BI9: 0.125 | BJ9: 0.1 | BL9: 0.125 | BM9: 0.11 | BN9: 0.1 | BO9: 1.2 | BP9: 1 | BQ9: 0.9 | BR9: 0.6 | BS9: 1.18 | BT9: 2.1 | BU9: 3.46 | CE9: =IFERROR(RATE(4,,BB9,-AY9),"") -> 0.065313515 | CF9: =IF(CE9>='Conviction List'!$D$4,1,"") | CG9: =IF(M7<='Conviction List'!$E$4,1,"") | CH9: =IF(BG9>='Conviction List'!$F$4,1,"") | CI9: =IF(BK9>='Conviction List'!$G$4,1,"") | CJ9: =SUM(CF9:CI9) -> 0 | CK9: =MATCH($D9,INDIRECT($C$90&"!$C$1:$C$164"),0) -> 11
B10: =B9+1 -> 8 | C10: Mishra Dhatu Nigam Limited (MIDHANI) | D10: MIDHANI | E10: MIDHANI | F10: =_xlfn.XLOOKUP(CCA_Defense!$D10,BB_Input!$C$4:$C$172,BB_Input!$G$4:$G$172) -> 649.82016 | G10: 1973 | H10: =YEAR(TODAY())-G10 -> 53 | I10: Listed | J10: Special alloys | M10: 73.81 | N10: =IFERROR(_xlfn.XLOOKUP($D10,PE_Projections!$D:$D,PE_Projections!L:L),"") -> 39.336703 | O10: =IFERROR(_xlfn.XLOOKUP($D10,PE_Projections!$D:$D,PE_Projections!M:M),"") -> 30.554466 | P10: =IFERROR(_xlfn.XLOOKUP($D10,PE_Projections!$D:$D,PE_Projections!N:N),"") -> 24.070352 | Q10: =IFERROR(_xlfn.XLOOKUP($D10,PE_Projections!$D:$D,PE_Projections!O:O),"") | R10: =IFERROR(_xlfn.XLOOKUP($D10,PE_Projections!$D:$D,PE_Projections!P:P),"") | S10: -12.63 | T10: =IFERROR(RATE(5,,BB10,-AY10),"") -> 0.053940666 | V10: =AVERAGE(80%,85%) -> 0.825 | W10: 1.9 | X10: {=_xlfn.IFS($F10<Glossary!$C$54,Glossary!$B$54,$F10<Glossary!$C$55,Glossary!$B$55,$F10>Glossary!$C$56,Glossary!$B$56)} -> Small Cap | Y10: Hyderabad | Z10: Government | AA10: 0.74 | AC10: High | AD10: High | AE10: High | AS10: Y | AU10: Tier 4 | AV10: 187.3 | AW10: 187.3 | AX10: 187.3 | AY10: 316 | AZ10: 290 | BA10: 266 | BB10: 243 | BC10: 33.95 | BH10: 0.15 | BI10: 0.14 | BJ10: 0.125 | BL10: 0.15 | BM10: 0.14 | BN10: 0.125 | BO10: 1.3 | BP10: 1.2 | BQ10: 1 | BR10: 0.8 | BS10: 0.25 | BT10: 0.3 | BU10: 0.22 | CE10: =IFERROR(RATE(4,,BB10,-AY10),"") -> 0.067874466 | CF10: =IF(CE10>='Conviction List'!$D$9,1,"") | CG10: =IF(M10<='Conviction List'!$E$9,1,"") -> 1 | CH10: =IF(BG10>='Conviction List'!$F$9,1,"") | CI10: =IF(BK10>='Conviction List'!$G$9,1,"") | CJ10: =SUM(CF10:CI10) -> 1 | CK10: =MATCH($D10,INDIRECT($C$90&"!$C$1:$C$164"),0) -> 12
B11: =B10+1 -> 9 | C11: Data Patterns | D11: DATAPATT | E11: DATAPATT | F11: =_xlfn.XLOOKUP(CCA_Defense!$D11,BB_Input!$C$4:$C$172,BB_Input!$G$4:$G$172) -> 1666.7202 | G11: 1985 | H11: =YEAR(TODAY())-G11 -> 41 | I11: Listed | J11: Avionics | N11: =IFERROR(_xlfn.XLOOKUP($D11,PE_Projections!$D:$D,PE_Projections!L:L),"") -> 48.318593 | O11: =IFERROR(_xlfn.XLOOKUP($D11,PE_Projections!$D:$D,PE_Projections!M:M),"") -> 38.101025 | P11: =IFERROR(_xlfn.XLOOKUP($D11,PE_Projections!$D:$D,PE_Projections!N:N),"") -> 29.124123 | Q11: =IFERROR(_xlfn.XLOOKUP($D11,PE_Projections!$D:$D,PE_Projections!O:O),"") -> 23.970579 | R11: =IFERROR(_xlfn.XLOOKUP($D11,PE_Projections!$D:$D,PE_Projections!P:P),"") | T11: =IFERROR(RATE(5,,BB11,-AY11),"") -> 0.19573801 | V11: 0.9 | W11: 1.3 | X11: {=_xlfn.IFS($F11<Glossary!$C$54,Glossary!$B$54,$F11<Glossary!$C$55,Glossary!$B$55,$F11>Glossary!$C$56,Glossary!$B$56)} -> Small Cap | Y11: Chennai | Z11: Private | AA11: 0.4241 | AB11: Singapore, 5.3% | AC11: High | AD11: High | AE11: High | AP11: Y | AQ11: Y | AU11: Tier 3 | AV11: 52.5 | AW11: 52.5 | AX11: 52.5 | AY11: 88 | AZ11: 66 | BA11: 54 | BB11: 36 | BC11: 51.8 | BG11: 0.1566 | BK11: 0.516 | BO11: 1.8 | BP11: 1.7 | BQ11: 1.5 | BR11: 1.4 | BS11: 0 | BT11: 0.01 | BU11: 0.16 | CE11: =IFERROR(RATE(4,,BB11,-AY11),"") -> 0.25038871 | CF11: =IF(CE11>='Conviction List'!$D$8,1,"") | CG11: =IF(M11<='Conviction List'!$E$8,1,"") -> 1 | CH11: =IF(BG11>='Conviction List'!$F$8,1,"") -> 1 | CI11: =IF(BK11>='Conviction List'!$G$8,1,"") -> 1 | CJ11: =SUM(CF11:CI11) -> 3 | CK11: =MATCH($D11,INDIRECT($C$90&"!$C$1:$C$164"),0) -> 13
B12: =B11+1 -> 10 | C12: Paras Defense and Space | D12: PARAS | E12: PARAS | F12: =_xlfn.XLOOKUP(CCA_Defense!$D12,BB_Input!$C$4:$C$172,BB_Input!$G$4:$G$172) -> 602.33536 | G12: 2009 | H12: =YEAR(TODAY())-G12 -> 17 | I12: Listed | J12: Electro-optics | M12: 105 | N12: =IFERROR(_xlfn.XLOOKUP($D12,PE_Projections!$D:$D,PE_Projections!L:L),"") -> 59.901788 | O12: =IFERROR(_xlfn.XLOOKUP($D12,PE_Projections!$D:$D,PE_Projections!M:M),"") -> 45.026847 | P12: =IFERROR(_xlfn.XLOOKUP($D12,PE_Projections!$D:$D,PE_Projections!N:N),"") | Q12: =IFERROR(_xlfn.XLOOKUP($D12,PE_Projections!$D:$D,PE_Projections!O:O),"") | R12: =IFERROR(_xlfn.XLOOKUP($D12,PE_Projections!$D:$D,PE_Projections!P:P),"") | S12: 47 | T12: =IFERROR(RATE(5,,BB12,-AY12),"") -> 0.10143233 | V12: =AVERAGE(80%,85%) -> 0.825 | W12: 2 | X12: {=_xlfn.IFS($F12<Glossary!$C$54,Glossary!$B$54,$F12<Glossary!$C$55,Glossary!$B$55,$F12>Glossary!$C$56,Glossary!$B$56)} -> Small Cap | Y12: Navi Mumbai | Z12: Private | AA12: 0.5705 | AB12: Abu Dhabi, 1.8% | AC12: High | AD12: High | AE12: High | AH12: Y | AQ12: Y | AU12: Tier 3 | AV12: 39.2 | AW12: 39.2 | AX12: 39.2 | AY12: =AZ12*(1+(RATE(3,,BB12,-AZ12,0))) -> 34.527784 | AZ12: 30.6 | BA12: 26 | BB12: 21.3 | BC12: 70.7 | BH12: 0.0796 | BI12: 0.0909 | BJ12: 0.0922 | BL12: 0.0968 | BM12: 0.1225 | BN12: 0.1032 | BO12: 1 | BP12: 0.9 | BQ12: 0.8 | BR12: 0.6 | BS12: 0.08 | BT12: 0 | BU12: 0.08 | CE12: =IFERROR(RATE(4,,BB12,-AY12),"") -> 0.12835894 | CF12: =IF(CE12>='Conviction List'!$D$8,1,"") | CG12: =IF(M12<='Conviction List'!$E$8,1,"") | CH12: =IF(BG12>='Conviction List'!$F$8,1,"") | CI12: =IF(BK12>='Conviction List'!$G$8,1,"") | CJ12: =SUM(CF12:CI12) -> 0 | CK12: =MATCH($D12,INDIRECT($C$90&"!$C$1:$C$164"),0) -> 14
B13: =B12+1 -> 11 | C13: Astra Microwave | D13: ASTM | E13: ASTM | F13: =_xlfn.XLOOKUP(CCA_Defense!$D13,BB_Input!$C$4:$C$172,BB_Input!$G$4:$G$172) -> 1026.2888 | G13: 1991 | H13: =YEAR(TODAY())-G13 -> 35 | I13: Listed | J13: RF/Microwave | L13: Yes | M13: 58.07 | N13: =IFERROR(_xlfn.XLOOKUP($D13,PE_Projections!$D:$D,PE_Projections!L:L),"") -> 53.831009 | O13: =IFERROR(_xlfn.XLOOKUP($D13,PE_Projections!$D:$D,PE_Projections!M:M),"") -> 44.264576 | P13: =IFERROR(_xlfn.XLOOKUP($D13,PE_Projections!$D:$D,PE_Projections!N:N),"") -> 36.398215 | Q13: =IFERROR(_xlfn.XLOOKUP($D13,PE_Projections!$D:$D,PE_Projections!O:O),"") -> 29.929804 | R13: =IFERROR(_xlfn.XLOOKUP($D13,PE_Projections!$D:$D,PE_Projections!P:P),"") -> 24.610909 | S13: 30.72 | T13: =IFERROR(RATE(5,,BB13,-AY13),"") -> 0.075507965 | U13: 0.26 | V13: =AVERAGE(80%,85%) -> 0.825 | W13: 2.1 | X13: {=_xlfn.IFS($F13<Glossary!$C$54,Glossary!$B$54,$F13<Glossary!$C$55,Glossary!$B$55,$F13>Glossary!$C$56,Glossary!$B$56)} -> Small Cap | Y13: Hyderabad | Z13: Private | AA13: 0.0654 | AB13: TEXINFRA, 2.2% | AC13: High | AD13: High | AE13: High | AQ13: Y | AR13: Y | AU13: Tier 3 | AV13: 91.2 | AW13: 91.2 | AX13: 91.2 | AY13: 118 | AZ13: 105 | BA13: 94 | BB13: 82 | BC13: 35.8 | BD13: 37.6 | BE13: 41 | BG13: 0.148 | BH13: 0.125 | BI13: 0.1 | BJ13: 0.09 | BK13: 0.1914 | BL13: 0.172 | BM13: 0.15 | BN13: 0.14 | BO13: 0.8 | BP13: 0.7 | BQ13: 0.5 | BR13: 0.4 | BS13: 0.23 | BT13: 0.26 | BU13: 0.1 | CE13: =IFERROR(RATE(4,,BB13,-AY13),"") -> 0.095259525 | CF13: =IF(CE13>='Conviction List'!$D$8,1,"") | CG13: =IF(M13<='Conviction List'!$E$8,1,"") -> 1 | CH13: =IF(BG13>='Conviction List'!$F$8,1,"") -> 1 | CI13: =IF(BK13>='Conviction List'!$G$8,1,"") | CJ13: =SUM(CF13:CI13) -> 2 | CK13: =MATCH($D13,INDIRECT($C$90&"!$C$1:$C$164"),0) -> 15
B14: =B13+1 -> 12 | C14: Axiscades Technologies Ltd | D14: AXET | E14: AXISCADES | F14: =_xlfn.XLOOKUP(CCA_Defense!$D14,BB_Input!$C$4:$C$172,BB_Input!$G$4:$G$172) -> 637.04539 | G14: 1990 | H14: =YEAR(TODAY())-G14 -> 36 | I14: Listed | J14: Engineering services | L14: Yes | M14: 76.1 | N14: =IFERROR(_xlfn.XLOOKUP($D14,PE_Projections!$D:$D,PE_Projections!L:L),"") -> 52.028001 | O14: =IFERROR(_xlfn.XLOOKUP($D14,PE_Projections!$D:$D,PE_Projections!M:M),"") -> 35.47271 | P14: =IFERROR(_xlfn.XLOOKUP($D14,PE_Projections!$D:$D,PE_Projections!N:N),"") -> 24.185307 | Q14: =IFERROR(_xlfn.XLOOKUP($D14,PE_Projections!$D:$D,PE_Projections!O:O),"") -> 16.489551 | R14: =IFERROR(_xlfn.XLOOKUP($D14,PE_Projections!$D:$D,PE_Projections!P:P),"") -> 11.242582 | S14: 10 | T14: =IFERROR(RATE(5,,BB14,-AY14),"") -> 0.1088115 | U14: 0.5439 | V14: =AVERAGE(60%,70%) -> 0.65 | W14: 1.68 | X14: {=_xlfn.IFS($F14<Glossary!$C$54,Glossary!$B$54,$F14<Glossary!$C$55,Glossary!$B$55,$F14>Glossary!$C$56,Glossary!$B$56)} -> Small Cap | Y14: Bengaluru | Z14: Private | AA14: 0.5949 | AC14: High | AD14: High | AE14: High | AF14: 70-80% of the projects are fixed under master service agreements; Axiscades was a key operator in setting up Airbus engineering facility in India & ~$30-35 Mn revenue comes from them per year. | AI14: Y | AM14: Y | AP14: Y | AQ14: Y | AR14: Y | AU14: Diversified | AV14: 37.7 | AW14: 37.7 | AX14: 37.7 | AY14: 119 | AZ14: 111 | BA14: 96 | BB14: 71 | BC14: 38.24 | BD14: 15.8 | BE14: 14.08 | BF14: 5.14 | BG14: 0.1261 | BH14: 0.056 | BI14: -0.0141 | BJ14: 0.0671 | BK14: 0.1357 | BL14: 0.1377 | BM14: 0.1041 | BN14: 0.1477 | BS14: 0.54 | BT14: 1.01 | BU14: 0.21 | CE14: =IFERROR(RATE(4,,BB14,-AY14),"") -> 0.13781631 | CF14: =IF(CE14>='Conviction List'!$D$4,1,"") | CG14: =IF(M12<='Conviction List'!$E$4,1,"") | CH14: =IF(BG14>='Conviction List'!$F$4,1,"") | CI14: =IF(BK14>='Conviction List'!$G$4,1,"") | CJ14: =SUM(CF14:CI14) -> 0 | CK14: =MATCH($D14,INDIRECT($C$90&"!$C$1:$C$164"),0) -> 37
B15: =B14+1 -> 13 | C15: DCX Systems | D15: DCXINDIA | E15: DCXINDIA | F15: =_xlfn.XLOOKUP(CCA_Defense!$D15,BB_Input!$C$4:$C$172,BB_Input!$G$4:$G$172) -> 251.06426 | G15: 2011 | H15: =YEAR(TODAY())-G15 -> 15 | I15: Listed | J15: Cable harnesses | M15: 67.45 | N15: =IFERROR(_xlfn.XLOOKUP($D15,PE_Projections!$D:$D,PE_Projections!L:L),"") -> 39.67059 | O15: =IFERROR(_xlfn.XLOOKUP($D15,PE_Projections!$D:$D,PE_Projections!M:M),"") -> 27.340542 | P15: =IFERROR(_xlfn.XLOOKUP($D15,PE_Projections!$D:$D,PE_Projections!N:N),"") -> 21.754839 | Q15: =IFERROR(_xlfn.XLOOKUP($D15,PE_Projections!$D:$D,PE_Projections!O:O),"") | R15: =IFERROR(_xlfn.XLOOKUP($D15,PE_Projections!$D:$D,PE_Projections!P:P),"") | T15: =IFERROR(RATE(5,,BB15,-AY15),"") -> 0.079915006 | V15: =AVERAGE(80%,85%) -> 0.825 | W15: 2.5 | X15: {=_xlfn.IFS($F15<Glossary!$C$54,Glossary!$B$54,$F15<Glossary!$C$55,Glossary!$B$55,$F15>Glossary!$C$56,Glossary!$B$56)} -> Small Cap | Y15: Bangalore | Z15: Private | AA15: 0.568 | AC15: High | AD15: High | AE15: High | AP15: Y | AQ15: Y | AU15: Tier 3 | AV15: 77.1 | AW15: 77.1 | AX15: 77.1 | AY15: 188 | AZ15: 165 | BA15: 145 | BB15: 128 | BC15: 25.37 | BL15: 0.1 | BM15: 0.13 | BN15: 0.22 | BO15: 0.3 | BP15: 0.4 | BQ15: 0.8 | BR15: 1.3 | BS15: 0.24 | BT15: 0.89 | BU15: 4.27 | CE15: =IFERROR(RATE(4,,BB15,-AY15),"") -> 0.10087237 | CF15: =IF(CE15>='Conviction List'!$D$8,1,"") | CG15: =IF(M15<='Conviction List'!$E$8,1,"") -> 1 | CH15: =IF(BG15>='Conviction List'!$F$8,1,"") | CI15: =IF(BK15>='Conviction List'!$G$8,1,"") | CJ15: =SUM(CF15:CI15) -> 1 | CK15: =MATCH($D15,INDIRECT($C$90&"!$C$1:$C$164"),0) -> 17
B16: =B15+1 -> 14 | C16: Avantel | D16: AVTS | E16: AVTS | F16: =_xlfn.XLOOKUP(CCA_Defense!$D16,BB_Input!$C$4:$C$172,BB_Input!$G$4:$G$172) -> 476.85876 | G16: 2010 | H16: =YEAR(TODAY())-G16 -> 16 | I16: Listed | J16: Satcom | N16: =IFERROR(_xlfn.XLOOKUP($D16,PE_Projections!$D:$D,PE_Projections!L:L),"") -> 61.963867 | O16: =IFERROR(_xlfn.XLOOKUP($D16,PE_Projections!$D:$D,PE_Projections!M:M),"") -> 51.794235 | P16: =IFERROR(_xlfn.XLOOKUP($D16,PE_Projections!$D:$D,PE_Projections!N:N),"") -> 43.293663 | Q16: =IFERROR(_xlfn.XLOOKUP($D16,PE_Projections!$D:$D,PE_Projections!O:O),"") -> 36.188222 | R16: =IFERROR(_xlfn.XLOOKUP($D16,PE_Projections!$D:$D,PE_Projections!P:P),"") -> 30.24894 | S16: 3 | T16: =IFERROR(RATE(5,,BB16,-AY16),"") -> 0.25927468 | V16: =AVERAGE(80%,85%) -> 0.825 | X16: {=_xlfn.IFS($F16<Glossary!$C$54,Glossary!$B$54,$F16<Glossary!$C$55,Glossary!$B$55,$F16>Glossary!$C$56,Glossary!$B$56)} -> Small Cap | Y16: Hyderabad | Z16: Family | AA16: 0.3857 | AC16: High | AD16: High | AE16: High | AP16: Y | AQ16: Y | AU16: Tier 3 | AV16: 17.2 | AW16: 17.2 | AX16: 17.2 | AY16: 38 | AZ16: 26 | BA16: 18 | BB16: 12 | BC16: 43.23 | BL16: 0.47 | BM16: 0.35 | BN16: 0.29 | BO16: 0.6 | BP16: 0.5 | BQ16: 0.4 | BR16: 0.3 | BS16: 0.07 | BT16: 0.25 | BU16: 0.15 | CE16: =IFERROR(RATE(4,,BB16,-AY16),"") -> 0.3339839 | CF16: =IF(CE16>='Conviction List'!$D$8,1,"") -> 1 | CG16: =IF(M16<='Conviction List'!$E$8,1,"") -> 1 | CH16: =IF(BG16>='Conviction List'!$F$8,1,"") | CI16: =IF(BK16>='Conviction List'!$G$8,1,"") | CJ16: =SUM(CF16:CI16) -> 2 | CK16: =MATCH($D16,INDIRECT($C$90&"!$C$1:$C$164"),0) -> 18
B17: =B16+1 -> 15 | C17: Apollo Micro Systems | D17: APOLLO | E17: APOLLO | F17: =_xlfn.XLOOKUP(CCA_Defense!$D17,BB_Input!$C$4:$C$172,BB_Input!$G$4:$G$172) -> 983.4285 | G17: 1997 | H17: =YEAR(TODAY())-G17 -> 29 | I17: Listed | J17: Systems integration | N17: =IFERROR(_xlfn.XLOOKUP($D17,PE_Projections!$D:$D,PE_Projections!L:L),"") -> 84.83871 | O17: =IFERROR(_xlfn.XLOOKUP($D17,PE_Projections!$D:$D,PE_Projections!M:M),"") -> 57.173913 | P17: =IFERROR(_xlfn.XLOOKUP($D17,PE_Projections!$D:$D,PE_Projections!N:N),"") -> 35.066667 | Q17: =IFERROR(_xlfn.XLOOKUP($D17,PE_Projections!$D:$D,PE_Projections!O:O),"") | R17: =IFERROR(_xlfn.XLOOKUP($D17,PE_Projections!$D:$D,PE_Projections!P:P),"") | T17: =IFERROR(RATE(5,,BB17,-AY17),"") -> 0.13611833 | V17: =AVERAGE(80%,85%) -> 0.825 | W17: 15.1 | X17: {=_xlfn.IFS($F17<Glossary!$C$54,Glossary!$B$54,$F17<Glossary!$C$55,Glossary!$B$55,$F17>Glossary!$C$56,Glossary!$B$56)} -> Small Cap | Y17: Hyderabad | Z17: Private | AA17: 0.5512 | AC17: High | AD17: High | AE17: High | AQ17: Y | AU17: Tier 3 | AV17: 51.7 | AW17: 51.7 | AX17: 51.7 | AY17: 53 | AZ17: 43 | BA17: 35 | BB17: 28 | BC17: 45.88 | BL17: 0.23 | BM17: 0.22 | BN17: 0.19 | BO17: 0.2 | BP17: 0.3 | BQ17: 0.4 | BR17: 0.5 | BS17: 0.84 | BT17: 0.8 | BU17: 0.87 | CE17: =IFERROR(RATE(4,,BB17,-AY17),"") -> 0.17294989 | CF17: =IF(CE17>='Conviction List'!$D$8,1,"") | CG17: =IF(M17<='Conviction List'!$E$8,1,"") -> 1 | CH17: =IF(BG17>='Conviction List'!$F$8,1,"") | CI17: =IF(BK17>='Conviction List'!$G$8,1,"") | CJ17: =SUM(CF17:CI17) -> 1 | CK17: =MATCH($D17,INDIRECT($C$90&"!$C$1:$C$164"),0) -> 19
B18: =B17+1 -> 16 | C18: Adani Elbit Advanced Systems India | D18: ADE | E18: ADANIENT | F18: =_xlfn.XLOOKUP(CCA_Defense!$D18,BB_Input!$C$4:$C$172,BB_Input!$G$4:$G$172) -> 31344.867 | G18: 2021 | H18: =YEAR(TODAY())-G18 -> 5 | I18: Acquired by/Part of Listed Company | J18: UAVs | M18: 105 | N18: =IFERROR(_xlfn.XLOOKUP($D18,PE_Projections!$D:$D,PE_Projections!L:L),"") -> 66.283299 | O18: =IFERROR(_xlfn.XLOOKUP($D18,PE_Projections!$D:$D,PE_Projections!M:M),"") -> 52.057927 | P18: =IFERROR(_xlfn.XLOOKUP($D18,PE_Projections!$D:$D,PE_Projections!N:N),"") -> 46.357758 | Q18: =IFERROR(_xlfn.XLOOKUP($D18,PE_Projections!$D:$D,PE_Projections!O:O),"") -> 50.407075 | R18: =IFERROR(_xlfn.XLOOKUP($D18,PE_Projections!$D:$D,PE_Projections!P:P),"") | T18: =IFERROR(RATE(5,,BB18,-AY18),"") -> 0.090495011 | V18: 1 | W18: 0.1 | X18: {=_xlfn.IFS($F18<Glossary!$C$54,Glossary!$B$54,$F18<Glossary!$C$55,Glossary!$B$55,$F18>Glossary!$C$56,Glossary!$B$56)} -> Large Cap | Y18: New Delhi | Z18: Family | AC18: High | AD18: High | AE18: High | AG18: Adani Enterprises Ltd on NSE/BSE & Elbit Systems Ltd. on NASDAQ | AH18: Y | AI18: Y | AJ18: Y | AM18: Y | AQ18: Y | AU18: Diversified | AY18: 78514 | AZ18: 67957 | BA18: 59465 | BB18: 50913 | CE18: =IFERROR(RATE(4,,BB18,-AY18),"") -> 0.11437049 | CF18: =IF(CE18>='Conviction List'!$D$4,1,"") | CG18: =IF(M16<='Conviction List'!$E$4,1,"") -> 1 | CH18: =IF(BG18>='Conviction List'!$F$4,1,"") | CI18: =IF(BK18>='Conviction List'!$G$4,1,"") | CJ18: =SUM(CF18:CI18) -> 1 | CK18: =MATCH($D18,INDIRECT($C$90&"!$C$1:$C$164"),0) -> 20
B19: =B18+1 -> 17 | C19: NIBE Ltd | D19: NIBE | E19: NIBE | F19: =_xlfn.XLOOKUP(CCA_Defense!$D19,BB_Input!$C$4:$C$172,BB_Input!$G$4:$G$172) -> 183.75245 | G19: 1986 | H19: =YEAR(TODAY())-G19 -> 40 | I19: Listed | J19: Connectors/Cables | M19: 59 | N19: =IFERROR(_xlfn.XLOOKUP($D19,PE_Projections!$D:$D,PE_Projections!L:L),"") -> 44.785977 | O19: =IFERROR(_xlfn.XLOOKUP($D19,PE_Projections!$D:$D,PE_Projections!M:M),"") -> 32.741084 | P19: =IFERROR(_xlfn.XLOOKUP($D19,PE_Projections!$D:$D,PE_Projections!N:N),"") -> 23.965091 | Q19: =IFERROR(_xlfn.XLOOKUP($D19,PE_Projections!$D:$D,PE_Projections!O:O),"") -> 17.854307 | R19: =IFERROR(_xlfn.XLOOKUP($D19,PE_Projections!$D:$D,PE_Projections!P:P),"") -> 13.527146 | T19: =IFERROR(RATE(5,,BB19,-AY19),"") -> 1.0662908 | V19: =AVERAGE(60%,70%) -> 0.65 | X19: {=_xlfn.IFS($F19<Glossary!$C$54,Glossary!$B$54,$F19<Glossary!$C$55,Glossary!$B$55,$F19>Glossary!$C$56,Glossary!$B$56)} -> Small Cap | Y19: Chakan | Z19: Family | AA19: 0.5374 | AC19: High | AD19: High | AE19: High | AQ19: Y | AU19: Tier 3 | AV19: 13.3 | AW19: 13.3 | AX19: 13.3 | AY19: 113 | AZ19: 32 | BA19: 12 | BB19: 3 | BC19: 38 | BD19: 44.1 | BH19: 0.142 | BO19: 3.9 | BP19: 3.9 | BQ19: 2.1 | BR19: 0.9 | BS19: 0.37 | BT19: 0.27 | BU19: 0.02 | CE19: =IFERROR(RATE(4,,BB19,-AY19),"") -> 1.477361 | CF19: =IF(CE19>='Conviction List'!$D$8,1,"") -> 1 | CG19: =IF(M19<='Conviction List'!$E$8,1,"") -> 1 | CH19: =IF(BG19>='Conviction List'!$F$8,1,"") | CI19: =IF(BK19>='Conviction List'!$G$8,1,"") | CJ19: =SUM(CF19:CI19) -> 2 | CK19: =MATCH($D19,INDIRECT($C$90&"!$C$1:$C$164"),0) -> 21
B20: =B19+1 -> 18 | C20: Azad Engineering | D20: AZAD | E20: AZAD | F20: =_xlfn.XLOOKUP(CCA_Defense!$D20,BB_Input!$C$4:$C$172,BB_Input!$G$4:$G$172) -> 1191.4721 | G20: 1983 | H20: =YEAR(TODAY())-G20 -> 43 | I20: Listed | J20: Aero-engine parts | L20: Yes | M20: 108 | N20: =IFERROR(_xlfn.XLOOKUP($D20,PE_Projections!$D:$D,PE_Projections!L:L),"") -> 84.328635 | O20: =IFERROR(_xlfn.XLOOKUP($D20,PE_Projections!$D:$D,PE_Projections!M:M),"") -> 55.772907 | P20: =IFERROR(_xlfn.XLOOKUP($D20,PE_Projections!$D:$D,PE_Projections!N:N),"") -> 36.886843 | Q20: =IFERROR(_xlfn.XLOOKUP($D20,PE_Projections!$D:$D,PE_Projections!O:O),"") -> 24.39606 | R20: =IFERROR(_xlfn.XLOOKUP($D20,PE_Projections!$D:$D,PE_Projections!P:P),"") -> 16.134961 | S20: 27 | T20: =IFERROR(RATE(5,,BB20,-AY20),"") -> 0.18772564 | U20: 0.44 | V20: =AVERAGE(60%,70%) -> 0.65 | W20: 6.3 | X20: {=_xlfn.IFS($F20<Glossary!$C$54,Glossary!$B$54,$F20<Glossary!$C$55,Glossary!$B$55,$F20>Glossary!$C$56,Glossary!$B$56)} -> Small Cap | Y20: Hyderabad | Z20: Family | AA20: 0.6032 | AC20: High | AD20: High | AE20: High | AT20: Y | AU20: Tier 4 | AV20: 78 | AW20: 78 | AX20: 78 | AY20: 52 | AZ20: 40 | BA20: 29 | BB20: 22 | BC20: 58.74 | BG20: 0.216 | BK20: 0.1223 | BL20: 0.22 | BM20: 0.16 | BN20: 0.22 | CE20: =IFERROR(RATE(4,,BB20,-AY20),"") -> 0.23992428 | CF20: =IF(CE20>='Conviction List'!$D$9,1,"") | CG20: =IF(M20<='Conviction List'!$E$9,1,"") -> 1 | CH20: =IF(BG20>='Conviction List'!$F$9,1,"") -> 1 | CI20: =IF(BK20>='Conviction List'!$G$9,1,"") -> 1 | CJ20: =SUM(CF20:CI20) -> 3 | CK20: =MATCH($D20,INDIRECT($C$90&"!$C$1:$C$164"),0) -> 27
B21: =B20+1 -> 19 | C21: Zen Technologies | D21: ZEN | E21: ZENTEC | F21: =_xlfn.XLOOKUP(CCA_Defense!$D21,BB_Input!$C$4:$C$172,BB_Input!$G$4:$G$172) -> 1399.8115 | G21: 1993 | H21: =YEAR(TODAY())-G21 -> 33 | I21: Listed | J21: Training simulators | L21: Yes | M21: 61 | N21: =IFERROR(_xlfn.XLOOKUP($D21,PE_Projections!$D:$D,PE_Projections!L:L),"") -> 46.506808 | O21: =IFERROR(_xlfn.XLOOKUP($D21,PE_Projections!$D:$D,PE_Projections!M:M),"") -> 30.078893 | P21: =IFERROR(_xlfn.XLOOKUP($D21,PE_Projections!$D:$D,PE_Projections!N:N),"") -> 23.192367 | Q21: =IFERROR(_xlfn.XLOOKUP($D21,PE_Projections!$D:$D,PE_Projections!O:O),"") | R21: =IFERROR(_xlfn.XLOOKUP($D21,PE_Projections!$D:$D,PE_Projections!P:P),"") | T21: =IFERROR(RATE(5,,BB21,-AY21),"") -> 0.39868042 | V21: =AVERAGE(70%,80%) -> 0.75 | W21: 1 | X21: {=_xlfn.IFS($F21<Glossary!$C$54,Glossary!$B$54,$F21<Glossary!$C$55,Glossary!$B$55,$F21>Glossary!$C$56,Glossary!$B$56)} -> Small Cap | Y21: Hyderabad | Z21: Family | AA21: 0.4905 | AC21: Medium | AD21: High | AE21: High | AR21: Y | AU21: Tier 3 | AV21: 83.2 | AW21: 83.2 | AX21: 83.2 | AY21: 91 | AZ21: 53 | BA21: 26 | BB21: 17 | BC21: 38.7 | BD21: 41.2 | BG21: 0.2608 | BH21: 0.269 | BI21: 0.085 | BJ21: 0.003 | BK21: 0.3671 | BL21: 0.33 | BS21: 0 | BT21: 0.02 | BU21: 0.04 | CE21: =IFERROR(RATE(4,,BB21,-AY21),"") -> 0.52106621 | CF21: =IF(CE21>='Conviction List'!$D$8,1,"") -> 1 | CG21: =IF(M21<='Conviction List'!$E$8,1,"") -> 1 | CH21: =IF(BG21>='Conviction List'!$F$8,1,"") -> 1 | CI21: =IF(BK21>='Conviction List'!$G$8,1,"") -> 1 | CJ21: =SUM(CF21:CI21) -> 4 | CK21: =MATCH($D21,INDIRECT($C$90&"!$C$1:$C$164"),0) -> 23
B22: =B21+1 -> 20 | C22: C2C Advanced Systems | D22: C2C | E22: C2C | F22: =_xlfn.XLOOKUP(CCA_Defense!$D22,BB_Input!$C$4:$C$172,BB_Input!$G$4:$G$172) -> 91.853865 | G22: 2012 | H22: =YEAR(TODAY())-G22 -> 14 | I22: Listed | J22: Command systems | L22: Yes | M22: 36 | N22: =IFERROR(_xlfn.XLOOKUP($D22,PE_Projections!$D:$D,PE_Projections!L:L),"") -> 20.472867 | O22: =IFERROR(_xlfn.XLOOKUP($D22,PE_Projections!$D:$D,PE_Projections!M:M),"") -> 17.930853 | P22: =IFERROR(_xlfn.XLOOKUP($D22,PE_Projections!$D:$D,PE_Projections!N:N),"") -> 15.704468 | Q22: =IFERROR(_xlfn.XLOOKUP($D22,PE_Projections!$D:$D,PE_Projections!O:O),"") -> 13.754523 | R22: =IFERROR(_xlfn.XLOOKUP($D22,PE_Projections!$D:$D,PE_Projections!P:P),"") -> 12.046692 | S22: 180 | T22: =IFERROR(RATE(5,,BB22,-AY22),"") | U22: 0.4427 | V22: 0.365 | X22: {=_xlfn.IFS($F22<Glossary!$C$54,Glossary!$B$54,$F22<Glossary!$C$55,Glossary!$B$55,$F22>Glossary!$C$56,Glossary!$B$56)} -> Small Cap | Y22: New Delhi | Z22: Private | AA22: 0.4145 | AC22: High | AD22: High | AE22: High | AF22: Heavy naval business mix dependant on relationships fostered by Cdr Narendra Lanka (COO) & CEO | AQ22: Y | AU22: Tier 3 | AV22: 16.64 | AW22: 17 | AX22: 1.5 | AY22: 13.2 | AZ22: 4.7 | BA22: 0.92 | BC22: 24.7 | BG22: 0.1774 | BH22: 0.1606 | BK22: 0.26 | BL22: 0.225 | BM22: 0.35 | BO22: 1.63 | BS22: 0.24 | CF22: =IF(CE22>='Conviction List'!$D$8,1,"") | CG22: =IF(M22<='Conviction List'!$E$8,1,"") -> 1 | CH22: =IF(BG22>='Conviction List'!$F$8,1,"") -> 1 | CI22: =IF(BK22>='Conviction List'!$G$8,1,"") -> 1 | CJ22: =SUM(CF22:CI22) -> 3 | CK22: =MATCH($D22,INDIRECT($C$90&"!$C$1:$C$164"),0) -> 71
B23: =B22+1 -> 21 | C23: Centum Electronics | D23: CTE | E23: CTE | F23: =_xlfn.XLOOKUP(CCA_Defense!$D23,BB_Input!$C$4:$C$172,BB_Input!$G$4:$G$172) -> 393.71613 | G23: 1993 | H23: =YEAR(TODAY())-G23 -> 33 | I23: Listed | J23: Space electronics | L23: Yes | N23: =IFERROR(_xlfn.XLOOKUP($D23,PE_Projections!$D:$D,PE_Projections!L:L),"") -> 65.524589 | O23: =IFERROR(_xlfn.XLOOKUP($D23,PE_Projections!$D:$D,PE_Projections!M:M),"") -> 35.955022 | P23: =IFERROR(_xlfn.XLOOKUP($D23,PE_Projections!$D:$D,PE_Projections!N:N),"") -> 22.949282 | Q23: =IFERROR(_xlfn.XLOOKUP($D23,PE_Projections!$D:$D,PE_Projections!O:O),"") | R23: =IFERROR(_xlfn.XLOOKUP($D23,PE_Projections!$D:$D,PE_Projections!P:P),"") | T23: =IFERROR(RATE(5,,BB23,-AY23),"") -> 0.072374264 | V23: =AVERAGE(60%,70%) -> 0.65 | W23: 12.8 | X23: {=_xlfn.IFS($F23<Glossary!$C$54,Glossary!$B$54,$F23<Glossary!$C$55,Glossary!$B$55,$F23>Glossary!$C$56,Glossary!$B$56)} -> Small Cap | Y23: Bangalore | Z23: Private | AA23: 0.5152 | AC23: High | AD23: High | AE23: High | AM23: Y | AP23: Y | AQ23: Y | AR23: Y | AU23: Diversified | AV23: 13.1 | AW23: 13.1 | AX23: 13.1 | AY23: 156 | AZ23: 139 | BA23: 127 | BB23: 110 | BC23: 33.4 | BD23: 10.5 | BE23: 12 | BH23: 0.18 | BI23: 0.165 | BJ23: 0.15 | BL23: 0.15 | BM23: 0.14 | BN23: 0.12 | BO23: 0 | BP23: 0 | BQ23: 0.1 | BR23: 0.3 | BS23: 0.85 | BT23: 1.25 | BU23: 1.34 | CE23: =IFERROR(RATE(4,,BB23,-AY23),"") -> 0.091271915 | CF23: =IF(CE23>='Conviction List'!$D$4,1,"") | CG23: =IF(M21<='Conviction List'!$E$4,1,"") -> 1 | CH23: =IF(BG23>='Conviction List'!$F$4,1,"") | CI23: =IF(BK23>='Conviction List'!$G$4,1,"") | CJ23: =SUM(CF23:CI23) -> 1 | CK23: =MATCH($D23,INDIRECT($C$90&"!$C$1:$C$164"),0) -> 16
B24: =B23+1 -> 22 | C24: IdeaForge Technology Ltd | D24: IDEAFORG | E24: IDEAFORGE | F24: =_xlfn.XLOOKUP(CCA_Defense!$D24,BB_Input!$C$4:$C$172,BB_Input!$G$4:$G$172) -> 231.34958 | G24: 2007 | H24: =YEAR(TODAY())-G24 -> 19 | I24: Listed | J24: UAVs | L24: Yes | N24: =IFERROR(_xlfn.XLOOKUP($D24,PE_Projections!$D:$D,PE_Projections!L:L),"") | O24: =IFERROR(_xlfn.XLOOKUP($D24,PE_Projections!$D:$D,PE_Projections!M:M),"") | P24: =IFERROR(_xlfn.XLOOKUP($D24,PE_Projections!$D:$D,PE_Projections!N:N),"") -> 27.268411 | Q24: =IFERROR(_xlfn.XLOOKUP($D24,PE_Projections!$D:$D,PE_Projections!O:O),"") -> 33.792365 | R24: =IFERROR(_xlfn.XLOOKUP($D24,PE_Projections!$D:$D,PE_Projections!P:P),"") -> 25.126303 | T24: =IFERROR(RATE(5,,BB24,-AY24),"") -> 0.25007157 | U24: 0.3449 | V24: =AVERAGE(50%,60%) -> 0.55 | W24: 0.7 | X24: {=_xlfn.IFS($F24<Glossary!$C$54,Glossary!$B$54,$F24<Glossary!$C$55,Glossary!$B$55,$F24>Glossary!$C$56,Glossary!$B$56)} -> Small Cap | Y24: Navi Mumbai | Z24: Private | AA24: 0.2917 | AC24: Medium | AD24: High | AE24: High | AF24: Heavy on R&D & mgmt mentioned that they tend to innovate even prior to RFQs from the govt which can be equated to "taking shots in the dark" | AH24: Y | AU24: Diversified | AV24: 43.8 | AW24: 43.8 | AX24: 43.8 | AY24: 58 | AZ24: 40 | BA24: 23 | BB24: 19 | BC24: -77.4 | BD24: 48.9 | BG24: -0.098 | BH24: 0.144 | BI24: 0.172 | BK24: -0.0936 | BL24: 0.496 | BM24: 0.125 | BN24: 0.112 | BS24: 0 | BT24: 0.27 | CE24: =IFERROR(RATE(4,,BB24,-AY24),"") -> 0.32180868 | CF24: =IF(CE24>='Conviction List'!$D$4,1,"") -> 1 | CG24: =IF(M22<='Conviction List'!$E$4,1,"") -> 1 | CH24: =IF(BG24>='Conviction List'!$F$4,1,"") | CI24: =IF(BK24>='Conviction List'!$G$4,1,"") | CJ24: =SUM(CF24:CI24) -> 2 | CK24: =MATCH($D24,INDIRECT($C$90&"!$C$1:$C$164"),0) -> 26
B25: =B24+1 -> 23 | C25: Cyient DLM Ltd | D25: CYIENTDL | E25: CYIENT | F25: =_xlfn.XLOOKUP(CCA_Defense!$D25,BB_Input!$C$4:$C$172,BB_Input!$G$4:$G$172) -> 376.52703 | G25: 2022 | H25: =YEAR(TODAY())-G25 -> 4 | I25: Listed | J25: EMS | L25: Yes | M25: 54.4 | N25: =IFERROR(_xlfn.XLOOKUP($D25,PE_Projections!$D:$D,PE_Projections!L:L),"") -> 39.887602 | O25: =IFERROR(_xlfn.XLOOKUP($D25,PE_Projections!$D:$D,PE_Projections!M:M),"") -> 26.816751 | P25: =IFERROR(_xlfn.XLOOKUP($D25,PE_Projections!$D:$D,PE_Projections!N:N),"") -> 20.122067 | Q25: =IFERROR(_xlfn.XLOOKUP($D25,PE_Projections!$D:$D,PE_Projections!O:O),"") -> 15.005286 | R25: =IFERROR(_xlfn.XLOOKUP($D25,PE_Projections!$D:$D,PE_Projections!P:P),"") | S25: 23 | T25: =IFERROR(RATE(5,,BB25,-AY25),"") -> 0.16353388 | V25: =AVERAGE(60%,70%) -> 0.65 | W25: 1.6 | X25: {=_xlfn.IFS($F25<Glossary!$C$54,Glossary!$B$54,$F25<Glossary!$C$55,Glossary!$B$55,$F25>Glossary!$C$56,Glossary!$B$56)} -> Small Cap | Y25: Bangalore | Z25: Private | AA25: 0.5216 | AB25: CYIENT, 52% | AC25: High | AD25: High | AE25: High | AP25: Y | AQ25: Y | AR25: Y | AU25: Tier 3 | AV25: 57.1 | AW25: 57.1 | AX25: 57.1 | AY25: 177 | AZ25: 138 | BA25: 96 | BB25: 83 | BC25: 23.32 | BG25: 0.0733 | BK25: 0.109 | BL25: 0.16 | BM25: 0.14 | BN25: 0.2 | BT25: 1.8 | BU25: 4.37 | CE25: =IFERROR(RATE(4,,BB25,-AY25),"") -> 0.20843639 | CF25: =IF(CE25>='Conviction List'!$D$8,1,"") | CG25: =IF(M25<='Conviction List'!$E$8,1,"") -> 1 | CH25: =IF(BG25>='Conviction List'!$F$8,1,"") | CI25: =IF(BK25>='Conviction List'!$G$8,1,"") | CJ25: =SUM(CF25:CI25) -> 1 | CK25: =MATCH($D25,INDIRECT($C$90&"!$C$1:$C$164"),0) -> 30
B26: =B25+1 -> 24 | C26: JayKay Enterprises | D26: JEL | E26: JAYKAY | F26: =_xlfn.XLOOKUP(CCA_Defense!$D26,BB_Input!$C$4:$C$172,BB_Input!$G$4:$G$172) -> 288.03437 | G26: 1978 | H26: =YEAR(TODAY())-G26 -> 48 | I26: Listed | J26: Holding company | M26: 100 | N26: =IFERROR(_xlfn.XLOOKUP($D26,PE_Projections!$D:$D,PE_Projections!L:L),"") -> 78.989184 | O26: =IFERROR(_xlfn.XLOOKUP($D26,PE_Projections!$D:$D,PE_Projections!M:M),"") -> 51.417814 | P26: =IFERROR(_xlfn.XLOOKUP($D26,PE_Projections!$D:$D,PE_Projections!N:N),"") -> 33.470299 | Q26: =IFERROR(_xlfn.XLOOKUP($D26,PE_Projections!$D:$D,PE_Projections!O:O),"") -> 21.787409 | R26: =IFERROR(_xlfn.XLOOKUP($D26,PE_Projections!$D:$D,PE_Projections!P:P),"") -> 14.18246 | S26: 202 | T26: =IFERROR(RATE(5,,BB26,-AY26),"") -> 0.67027765 | V26: =AVERAGE(50%,60%) -> 0.55 | X26: {=_xlfn.IFS($F26<Glossary!$C$54,Glossary!$B$54,$F26<Glossary!$C$55,Glossary!$B$55,$F26>Glossary!$C$56,Glossary!$B$56)} -> Small Cap | Y26: Mumbai | Z26: Family | AA26: 0.6331 | AC26: High | AD26: High | AE26: High | AT26: Y | AU26: Tier 4 | AV26: 72.3 | AW26: 72.3 | AX26: 72.3 | AY26: 13 | AZ26: 6 | BA26: 5 | BB26: 1 | BC26: 70.38 | BG26: 0.143 | BK26: 0.033 | BL26: 0.17 | BM26: 0.03 | BN26: 0.04 | BS26: 0.02 | BT26: 0 | BU26: 0 | CE26: =IFERROR(RATE(4,,BB26,-AY26),"") -> 0.89882892 | CF26: =IF(CE26>='Conviction List'!$D$9,1,"") -> 1 | CG26: =IF(M26<='Conviction List'!$E$9,1,"") -> 1 | CH26: =IF(BG26>='Conviction List'!$F$9,1,"") -> 1 | CI26: =IF(BK26>='Conviction List'!$G$9,1,"") | CJ26: =SUM(CF26:CI26) -> 3 | CK26: =MATCH($D26,INDIRECT($C$90&"!$C$1:$C$164"),0) -> 28
B27: =B26+1 -> 25 | C27: Sika Interplant Systems | D27: SIKA | E27: SIKA | F27: =_xlfn.XLOOKUP(CCA_Defense!$D27,BB_Input!$C$4:$C$172,BB_Input!$G$4:$G$172) -> 213.04636 | G27: 1993 | H27: =YEAR(TODAY())-G27 -> 33 | I27: Listed | J27: Aerospace tooling | M27: 82 | N27: =IFERROR(_xlfn.XLOOKUP($D27,PE_Projections!$D:$D,PE_Projections!L:L),"") -> 73.677848 | O27: =IFERROR(_xlfn.XLOOKUP($D27,PE_Projections!$D:$D,PE_Projections!M:M),"") -> 69.220969 | P27: =IFERROR(_xlfn.XLOOKUP($D27,PE_Projections!$D:$D,PE_Projections!N:N),"") -> 66.946448 | Q27: =IFERROR(_xlfn.XLOOKUP($D27,PE_Projections!$D:$D,PE_Projections!O:O),"") -> 64.746665 | R27: =IFERROR(_xlfn.XLOOKUP($D27,PE_Projections!$D:$D,PE_Projections!P:P),"") -> 60.879744 | S27: 58 | T27: =IFERROR(RATE(5,,BB27,-AY27),"") -> 0.033975227 | V27: =AVERAGE(80%,85%) -> 0.825 | X27: {=_xlfn.IFS($F27<Glossary!$C$54,Glossary!$B$54,$F27<Glossary!$C$55,Glossary!$B$55,$F27>Glossary!$C$56,Glossary!$B$56)} -> Small Cap | Y27: Bangalore | Z27: Family | AA27: 0.7172 | AC27: High | AD27: High | AE27: High | AP27: Y | AQ27: Y | AU27: Tier 3 | AV27: 3.4 | AW27: 3.4 | AX27: 3.4 | AY27: 13 | AZ27: 12 | BA27: 7 | BB27: 11 | BC27: 90.49 | BG27: 0.2204 | BK27: 0.2904 | BL27: 0.26 | BM27: 0.15 | BN27: 0.31 | BS27: 2.84 | BT27: 3.14 | BU27: 0 | CE27: =IFERROR(RATE(4,,BB27,-AY27),"") -> 0.042647885 | CF27: =IF(CE27>='Conviction List'!$D$8,1,"") | CG27: =IF(M27<='Conviction List'!$E$8,1,"") -> 1 | CH27: =IF(BG27>='Conviction List'!$F$8,1,"") -> 1 | CI27: =IF(BK27>='Conviction List'!$G$8,1,"") -> 1 | CJ27: =SUM(CF27:CI27) -> 3 | CK27: =MATCH($D27,INDIRECT($C$90&"!$C$1:$C$164"),0) -> 29
B28: =B27+1 -> 26 | C28: Dynamatic Technologies Ltd | D28: DYTC | E28: DYNAMATECH | F28: =_xlfn.XLOOKUP(CCA_Defense!$D28,BB_Input!$C$4:$C$172,BB_Input!$G$4:$G$172) -> 731.76171 | G28: 1973 | H28: =YEAR(TODAY())-G28 -> 53 | I28: Listed | J28: Aerostructures | L28: Yes | M28: 113 | N28: =IFERROR(_xlfn.XLOOKUP($D28,PE_Projections!$D:$D,PE_Projections!L:L),"") -> 124.15276 | O28: =IFERROR(_xlfn.XLOOKUP($D28,PE_Projections!$D:$D,PE_Projections!M:M),"") -> 68.013361 | P28: =IFERROR(_xlfn.XLOOKUP($D28,PE_Projections!$D:$D,PE_Projections!N:N),"") -> 48.576092 | Q28: =IFERROR(_xlfn.XLOOKUP($D28,PE_Projections!$D:$D,PE_Projections!O:O),"") -> 25.326682 | R28: =IFERROR(_xlfn.XLOOKUP($D28,PE_Projections!$D:$D,PE_Projections!P:P),"") | S28: -2 | T28: =IFERROR(RATE(5,,BB28,-AY28),"") -> 0.022702436 | V28: =AVERAGE(55%,60%) -> 0.575 | W28: 6.8 | X28: {=_xlfn.IFS($F28<Glossary!$C$54,Glossary!$B$54,$F28<Glossary!$C$55,Glossary!$B$55,$F28>Glossary!$C$56,Glossary!$B$56)} -> Small Cap | Y28: Bangalore | Z28: Private | AA28: 0.48 | AC28: High | AD28: High | AE28: High | AG28: Dr. Udayant Malhoutra is the Promoter & CEO | AK28: Y | AL28: Y | AU28: Tier 1 | AV28: 6.3 | AW28: 6.3 | AX28: 6.3 | AY28: 162 | AZ28: 165 | BA28: 152 | BB28: 144.8 | BC28: 30.16 | BG28: 0.062 | BK28: 0.088 | CF28: =IF(CE28>='Conviction List'!$D$8,1,"") | CG28: =IF(M28<='Conviction List'!$E$8,1,"") | CH28: =IF(BG28>='Conviction List'!$F$8,1,"") | CI28: =IF(BK28>='Conviction List'!$G$8,1,"") | CJ28: =SUM(CF28:CI28) -> 0 | CK28: =MATCH($D28,INDIRECT($C$90&"!$C$1:$C$164"),0) -> 48
B29: =B28+1 -> 27 | C29: Kaynes Technology Ltd | D29: KAYNES | E29: KAYNES | F29: =_xlfn.XLOOKUP(CCA_Defense!$D29,BB_Input!$C$4:$C$172,BB_Input!$G$4:$G$172) -> 3075.7585 | G29: 2008 | H29: =YEAR(TODAY())-G29 -> 18 | I29: Listed | J29: EMS | L29: Yes | M29: 146 | N29: =IFERROR(_xlfn.XLOOKUP($D29,PE_Projections!$D:$D,PE_Projections!L:L),"") -> 58.586449 | O29: =IFERROR(_xlfn.XLOOKUP($D29,PE_Projections!$D:$D,PE_Projections!M:M),"") -> 42.16206 | P29: =IFERROR(_xlfn.XLOOKUP($D29,PE_Projections!$D:$D,PE_Projections!N:N),"") -> 30.930776 | Q29: =IFERROR(_xlfn.XLOOKUP($D29,PE_Projections!$D:$D,PE_Projections!O:O),"") -> 20.724359 | R29: =IFERROR(_xlfn.XLOOKUP($D29,PE_Projections!$D:$D,PE_Projections!P:P),"") | S29: 111 | T29: =IFERROR(RATE(5,,BB29,-AY29),"") -> 0.27657457 | V29: =AVERAGE(50%,60%) -> 0.55 | W29: 3.2 | X29: {=_xlfn.IFS($F29<Glossary!$C$54,Glossary!$B$54,$F29<Glossary!$C$55,Glossary!$B$55,$F29>Glossary!$C$56,Glossary!$B$56)} -> Mid Cap | Y29: Mysore | Z29: Family | AA29: 0.5775 | AC29: Medium | AD29: High | AE29: High | AQ29: Y | AU29: Tier 3 | AV29: 36.5 | AW29: 36.5 | AX29: 36.5 | AY29: 278 | AZ29: 211 | BA29: 131 | BB29: 82 | BC29: 79.16 | BD29: 56 | BE29: 26 | BG29: 0.1102 | BH29: 0.0737 | BI29: 0.0993 | BJ29: 0.2057 | BK29: 0.144 | BL29: 0.1127 | BM29: 0.1604 | BN29: 0.3216 | BO29: 3.08 | BS29: 0.11 | BT29: 0.13 | BU29: 0.14 | CE29: =IFERROR(RATE(4,,BB29,-AY29),"") -> 0.35693091 | CF29: =IF(CE29>='Conviction List'!$D$8,1,"") -> 1 | CG29: =IF(M29<='Conviction List'!$E$8,1,"") | CH29: =IF(BG29>='Conviction List'!$F$8,1,"") | CI29: =IF(BK29>='Conviction List'!$G$8,1,"") | CJ29: =SUM(CF29:CI29) -> 1 | CK29: =MATCH($D29,INDIRECT($C$90&"!$C$1:$C$164"),0) -> 31
B30: =B29+1 -> 28 | C30: Syrma SGS Technology Ltd | D30: SYRMA | E30: SYRMA | F30: =_xlfn.XLOOKUP(CCA_Defense!$D30,BB_Input!$C$4:$C$172,BB_Input!$G$4:$G$172) -> 1576.5101 | G30: 1991 | H30: =YEAR(TODAY())-G30 -> 35 | I30: Listed | J30: EMS | M30: 62 | N30: =IFERROR(_xlfn.XLOOKUP($D30,PE_Projections!$D:$D,PE_Projections!L:L),"") -> 52.869449 | O30: =IFERROR(_xlfn.XLOOKUP($D30,PE_Projections!$D:$D,PE_Projections!M:M),"") -> 36.643397 | P30: =IFERROR(_xlfn.XLOOKUP($D30,PE_Projections!$D:$D,PE_Projections!N:N),"") -> 27.262702 | Q30: =IFERROR(_xlfn.XLOOKUP($D30,PE_Projections!$D:$D,PE_Projections!O:O),"") -> 19.449008 | R30: =IFERROR(_xlfn.XLOOKUP($D30,PE_Projections!$D:$D,PE_Projections!P:P),"") | T30: =IFERROR(RATE(5,,BB30,-AY30),"") -> 0.30068267 | V30: =AVERAGE(40%,50%) -> 0.45 | W30: 1.4 | X30: {=_xlfn.IFS($F30<Glossary!$C$54,Glossary!$B$54,$F30<Glossary!$C$55,Glossary!$B$55,$F30>Glossary!$C$56,Glossary!$B$56)} -> Small Cap | Y30: Chennai | Z30: Private | AA30: 0.4653 | AC30: High | AD30: High | AE30: High | AP30: Y | AQ30: Y | AU30: Tier 3 | AV30: 176.8 | AW30: 176.8 | AX30: 176.8 | AY30: 443 | AZ30: 369 | BA30: 240 | BB30: 119 | BC30: 29.82 | BD30: 97.2 | BE30: 44.3 | BF30: 19.46 | BG30: 0.1019 | BH30: 0.0666 | BI30: 0.0775 | BJ30: 0.0971 | BK30: 0.1241 | BL30: 0.0345 | BM30: 0.0645 | BN30: 0.0927 | BO30: 3.6 | BS30: 0.34 | BT30: 0.22 | BU30: 0.33 | CE30: =IFERROR(RATE(4,,BB30,-AY30),"") -> 0.38903821 | CF30: =IF(CE30>='Conviction List'!$D$8,1,"") -> 1 | CG30: =IF(M30<='Conviction List'!$E$8,1,"") -> 1 | CH30: =IF(BG30>='Conviction List'!$F$8,1,"") | CI30: =IF(BK30>='Conviction List'!$G$8,1,"") | CJ30: =SUM(CF30:CI30) -> 2 | CK30: =MATCH($D30,INDIRECT($C$90&"!$C$1:$C$164"),0) -> 32
B31: =B30+1 -> 29 | C31: Solar Industries India Ltd | D31: SOIL | E31: SOLARINDS | F31: =_xlfn.XLOOKUP(CCA_Defense!$D31,BB_Input!$C$4:$C$172,BB_Input!$G$4:$G$172) -> 12586.448 | G31: 1995 | H31: =YEAR(TODAY())-G31 -> 31 | I31: Listed | J31: Explosives | M31: 108 | N31: =IFERROR(_xlfn.XLOOKUP($D31,PE_Projections!$D:$D,PE_Projections!L:L),"") -> 66.813536 | O31: =IFERROR(_xlfn.XLOOKUP($D31,PE_Projections!$D:$D,PE_Projections!M:M),"") -> 52.071217 | P31: =IFERROR(_xlfn.XLOOKUP($D31,PE_Projections!$D:$D,PE_Projections!N:N),"") -> 43.450835 | Q31: =IFERROR(_xlfn.XLOOKUP($D31,PE_Projections!$D:$D,PE_Projections!O:O),"") -> 34.141873 | R31: =IFERROR(_xlfn.XLOOKUP($D31,PE_Projections!$D:$D,PE_Projections!P:P),"") | S31: 9 | T31: =IFERROR(RATE(5,,BB31,-AY31),"") -> 0.12104299 | V31: 5-9% | W31: 2.2 | X31: {=_xlfn.IFS($F31<Glossary!$C$54,Glossary!$B$54,$F31<Glossary!$C$55,Glossary!$B$55,$F31>Glossary!$C$56,Glossary!$B$56)} -> Large Cap | Y31: Nagpur | Z31: Family | AA31: 0.7315 | AC31: High | AD31: High | AE31: High | AH31: Y | AM31: Y | AN31: Y | AO31: Y | AU31: Diversified | AY31: 818 | AZ31: 711 | BA31: 810 | BB31: 462 | BC31: 72.41 | BD31: 56.8 | BE31: 27.84 | BF31: 19.92 | BG31: 0.3264 | BH31: 0.2529 | BI31: 0.2901 | BJ31: 0.235 | BK31: 0.3813 | BL31: 0.299 | BM31: 0.334 | BN31: 0.275 | BS31: 0.19 | BT31: 0.35 | BU31: 0.41 | CE31: =IFERROR(RATE(4,,BB31,-AY31),"") -> 0.15352718 | CF31: =IF(CE31>='Conviction List'!$D$4,1,"") | CG31: =IF(M29<='Conviction List'!$E$4,1,"") | CH31: =IF(BG31>='Conviction List'!$F$4,1,"") -> 1 | CI31: =IF(BK31>='Conviction List'!$G$4,1,"") -> 1 | CJ31: =SUM(CF31:CI31) -> 2 | CK31: =MATCH($D31,INDIRECT($C$90&"!$C$1:$C$164"),0) -> 33
B32: =B31+1 -> 30 | C32: Bharat Forge Ltd | D32: BHFC | E32: BHARATFORG | F32: =_xlfn.XLOOKUP(CCA_Defense!$D32,BB_Input!$C$4:$C$172,BB_Input!$G$4:$G$172) -> 7725.7373 | G32: 1961 | H32: =YEAR(TODAY())-G32 -> 65 | I32: Listed | J32: Defence forgings | M32: 58 | N32: =IFERROR(_xlfn.XLOOKUP($D32,PE_Projections!$D:$D,PE_Projections!L:L),"") -> 54.214166 | O32: =IFERROR(_xlfn.XLOOKUP($D32,PE_Projections!$D:$D,PE_Projections!M:M),"") -> 40.96701 | P32: =IFERROR(_xlfn.XLOOKUP($D32,PE_Projections!$D:$D,PE_Projections!N:N),"") -> 34.129733 | Q32: =IFERROR(_xlfn.XLOOKUP($D32,PE_Projections!$D:$D,PE_Projections!O:O),"") -> 25.76491 | R32: =IFERROR(_xlfn.XLOOKUP($D32,PE_Projections!$D:$D,PE_Projections!P:P),"") | S32: -4 | T32: =IFERROR(RATE(5,,BB32,-AY32),"") -> 0.076451952 | V32: =AVERAGE(10%,15%) -> 0.125 | W32: 9.2 | X32: {=_xlfn.IFS($F32<Glossary!$C$54,Glossary!$B$54,$F32<Glossary!$C$55,Glossary!$B$55,$F32>Glossary!$C$56,Glossary!$B$56)} -> Mid Cap | Y32: Pune | Z32: Government | AA32: 0.44078 | AC32: High | AD32: High | AE32: High | AI32: Y | AK32: Y | AL32: Y | AM32: Y | AN32: Y | AQ32: Y | AU32: Diversified | AV32: 466 | AW32: 466 | AX32: 466 | AY32: 1772 | AZ32: 1827 | BA32: 1513 | BB32: 1226 | BC32: 23.27 | BD32: 21.08 | BE32: 22.3 | BF32: 16.14 | BG32: 0.1227 | BH32: 0.1327 | BI32: 0.0788 | BJ32: 0.1646 | BK32: 0.1309 | BL32: 0.1912 | BM32: 0.1147 | BN32: 0.1667 | BS32: 0.52 | BT32: 0.58 | BU32: 0.2 | CE32: =IFERROR(RATE(4,,BB32,-AY32),"") -> 0.09646131 | CF32: =IF(CE32>='Conviction List'!$D$4,1,"") | CG32: =IF(M30<='Conviction List'!$E$4,1,"") -> 1 | CH32: =IF(BG32>='Conviction List'!$F$4,1,"") | CI32: =IF(BK32>='Conviction List'!$G$4,1,"") | CJ32: =SUM(CF32:CI32) -> 1 | CK32: =MATCH($D32,INDIRECT($C$90&"!$C$1:$C$164"),0) -> 34
B33: =B32+1 -> 31 | C33: Larsen & Toubro Ltd (L&T) | D33: LT | E33: LT | F33: =_xlfn.XLOOKUP(CCA_Defense!$D33,BB_Input!$C$4:$C$172,BB_Input!$G$4:$G$172) -> 62121.34 | G33: 1946 | H33: =YEAR(TODAY())-G33 -> 80 | I33: Acquired by/Part of Listed Company | J33: Defence EPC | M33: 33 | N33: =IFERROR(_xlfn.XLOOKUP($D33,PE_Projections!$D:$D,PE_Projections!L:L),"") -> 30.839425 | O33: =IFERROR(_xlfn.XLOOKUP($D33,PE_Projections!$D:$D,PE_Projections!M:M),"") -> 25.364498 | P33: =IFERROR(_xlfn.XLOOKUP($D33,PE_Projections!$D:$D,PE_Projections!N:N),"") -> 21.507315 | Q33: =IFERROR(_xlfn.XLOOKUP($D33,PE_Projections!$D:$D,PE_Projections!O:O),"") -> 18.582136 | R33: =IFERROR(_xlfn.XLOOKUP($D33,PE_Projections!$D:$D,PE_Projections!P:P),"") | S33: 16 | T33: =IFERROR(RATE(5,,BB33,-AY33),"") -> 0.10317481 | V33: 0.05 | W33: 3 | X33: {=_xlfn.IFS($F33<Glossary!$C$54,Glossary!$B$54,$F33<Glossary!$C$55,Glossary!$B$55,$F33>Glossary!$C$56,Glossary!$B$56)} -> Large Cap | Y33: Mumbai | Z33: Private | AA33: 0.198 | AC33: High | AD33: High | AE33: High | AG33: L&T | AJ33: Y | AT33: Y | AU33: Diversified | AV33: 1403 | AW33: 1403 | AX33: 1403 | AY33: 29972 | AZ33: 25914 | BA33: 21487 | BB33: 18344 | BC33: 15.8 | BD33: 22.55 | BE33: 17.05 | BF33: 17.4 | BG33: 0.1655 | BH33: 0.1512 | BI33: 0.1172 | BJ33: 0.1049 | BK33: 0.1449 | BL33: 0.1476 | BM33: 0.1207 | BN33: 0.1098 | BS33: 0.35 | BT33: 0.25 | BU33: 0.3 | CE33: =IFERROR(RATE(4,,BB33,-AY33),"") -> 0.13059073 | CF33: =IF(CE33>='Conviction List'!$D$4,1,"") | CG33: =IF(M31<='Conviction List'!$E$4,1,"") | CH33: =IF(BG33>='Conviction List'!$F$4,1,"") -> 1 | CI33: =IF(BK33>='Conviction List'!$G$4,1,"") | CJ33: =SUM(CF33:CI33) -> 1 | CK33: =MATCH($D33,INDIRECT($C$90&"!$C$1:$C$164"),0) -> 35
B34: =B33+1 -> 32 | C34: Bharat Heavy Electricals Ltd | D34: BHEL | E34: BHEL | F34: =_xlfn.XLOOKUP(CCA_Defense!$D34,BB_Input!$C$4:$C$172,BB_Input!$G$4:$G$172) -> 10792.141 | G34: 1964 | H34: =YEAR(TODAY())-G34 -> 62 | I34: Listed | J34: Heavy engineering | M34: 156 | N34: =IFERROR(_xlfn.XLOOKUP($D34,PE_Projections!$D:$D,PE_Projections!L:L),"") -> 55.68455 | O34: =IFERROR(_xlfn.XLOOKUP($D34,PE_Projections!$D:$D,PE_Projections!M:M),"") -> 31.449244 | P34: =IFERROR(_xlfn.XLOOKUP($D34,PE_Projections!$D:$D,PE_Projections!N:N),"") -> 22.968009 | Q34: =IFERROR(_xlfn.XLOOKUP($D34,PE_Projections!$D:$D,PE_Projections!O:O),"") | R34: =IFERROR(_xlfn.XLOOKUP($D34,PE_Projections!$D:$D,PE_Projections!P:P),"") | S34: 16 | T34: =IFERROR(RATE(5,,BB34,-AY34),"") -> 0.054167392 | V34: =AVERAGE(5%,10%) -> 0.075 | W34: 7.4 | X34: {=_xlfn.IFS($F34<Glossary!$C$54,Glossary!$B$54,$F34<Glossary!$C$55,Glossary!$B$55,$F34>Glossary!$C$56,Glossary!$B$56)} -> Large Cap | Y34: New Delhi | Z34: Government | AA34: 0.6317 | AC34: High | AD34: High | AE34: High | AI34: Y | AJ34: Y | AK34: Y | AL34: Y | AM34: Y | AR34: Y | AU34: Diversified | AV34: 3476 | AW34: 3476 | AX34: 3476 | AY34: 3235 | AZ34: 2800 | BA34: 2738 | BB34: 2485 | BC34: 51.9 | BD34: 76.6 | BE34: 21.11 | BF34: 18.6 | BG34: 0.0217 | BH34: 0.0115 | BI34: 0.0157 | BJ34: 0.0168 | BK34: 0.0446 | BL34: 0.027 | BM34: 0.026 | BN34: 0.0237 | BS34: 0 | BT34: 0 | BU34: 0 | CE34: =IFERROR(RATE(4,,BB34,-AY34),"") -> 0.068161629 | CF34: =IF(CE34>='Conviction List'!$D$4,1,"") | CG34: =IF(M32<='Conviction List'!$E$4,1,"") -> 1 | CH34: =IF(BG34>='Conviction List'!$F$4,1,"") | CI34: =IF(BK34>='Conviction List'!$G$4,1,"") | CJ34: =SUM(CF34:CI34) -> 1 | CK34: =MATCH($D34,INDIRECT($C$90&"!$C$1:$C$164"),0) -> 36
B35: =B34+1 -> 33 | C35: Kavveri Defence & Wireless Tech | D35: KAVDEFEN | E35: KAVDEFENCE | F35: =_xlfn.XLOOKUP(CCA_Defense!$D35,BB_Input!$C$4:$C$172,BB_Input!$G$4:$G$172) -> 30.544449 | G35: 2014 | H35: =YEAR(TODAY())-G35 -> 12 | I35: Listed | J35: RF antennas | L35: Yes | M35: 31.6 | N35: =IFERROR(_xlfn.XLOOKUP($D35,PE_Projections!$D:$D,PE_Projections!L:L),"") -> 61.262396 | O35: =IFERROR(_xlfn.XLOOKUP($D35,PE_Projections!$D:$D,PE_Projections!M:M),"") -> 41.105771 | P35: =IFERROR(_xlfn.XLOOKUP($D35,PE_Projections!$D:$D,PE_Projections!N:N),"") -> 27.581102 | Q35: =IFERROR(_xlfn.XLOOKUP($D35,PE_Projections!$D:$D,PE_Projections!O:O),"") -> 18.506335 | R35: =IFERROR(_xlfn.XLOOKUP($D35,PE_Projections!$D:$D,PE_Projections!P:P),"") -> 12.417359 | S35: 977 | T35: =IFERROR(RATE(5,,BB35,-AY35),"") | U35: 0.406 | X35: {=_xlfn.IFS($F35<Glossary!$C$54,Glossary!$B$54,$F35<Glossary!$C$55,Glossary!$B$55,$F35>Glossary!$C$56,Glossary!$B$56)} -> Small Cap | Y35: Bangalore | Z35: Private | AA35: 0.1541 | AC35: High | AD35: High | AE35: High | AF35: Started as a telco operator & pivoted into RF Antennas after issues a large order from Videotron was written off around 2014 | AU35: Tier 3 | CF35: =IF(CE35>='Conviction List'!$D$8,1,"") | CG35: =IF(M35<='Conviction List'!$E$8,1,"") -> 1 | CH35: =IF(BG35>='Conviction List'!$F$8,1,"") | CI35: =IF(BK35>='Conviction List'!$G$8,1,"") | CJ35: =SUM(CF35:CI35) -> 1 | CK35: =MATCH($D35,INDIRECT($C$90&"!$C$1:$C$164"),0) -> 79
B36: =B35+1 -> 34 | C36: Taneja Aerospace & Aviation Ltd | D36: TAA | E36: TANEJAERO | F36: =_xlfn.XLOOKUP(CCA_Defense!$D36,BB_Input!$C$4:$C$172,BB_Input!$G$4:$G$172) -> 83.637471 | G36: 2005 | H36: =YEAR(TODAY())-G36 -> 21 | I36: Listed | J36: Aerostructures | M36: 53.5 | N36: =IFERROR(_xlfn.XLOOKUP($D36,PE_Projections!$D:$D,PE_Projections!L:L),"") -> 150.81606 | O36: =IFERROR(_xlfn.XLOOKUP($D36,PE_Projections!$D:$D,PE_Projections!M:M),"") -> 140.63933 | P36: =IFERROR(_xlfn.XLOOKUP($D36,PE_Projections!$D:$D,PE_Projections!N:N),"") -> 131.1493 | Q36: =IFERROR(_xlfn.XLOOKUP($D36,PE_Projections!$D:$D,PE_Projections!O:O),"") -> 122.29964 | R36: =IFERROR(_xlfn.XLOOKUP($D36,PE_Projections!$D:$D,PE_Projections!P:P),"") -> 114.04714 | S36: 13 | T36: =IFERROR(RATE(5,,BB36,-AY36),"") -> 0.021295688 | V36: =AVERAGE(70%,80%) -> 0.75 | X36: {=_xlfn.IFS($F36<Glossary!$C$54,Glossary!$B$54,$F36<Glossary!$C$55,Glossary!$B$55,$F36>Glossary!$C$56,Glossary!$B$56)} -> Small Cap | Y36: Hosur | Z36: Private | AA36: 0.522 | AC36: High | AD36: High | AE36: High | AK36: Y | AL36: Y | AU36: Tier 1 | AV36: 17.6 | AW36: 17.6 | AX36: 17.6 | AY36: 4 | AZ36: 2.5 | BA36: 3.7 | BB36: 3.6 | BC36: 43.47 | BG36: 0.1326 | BK36: 0.1745 | BS36: 0 | BT36: 0 | BU36: 0.03 | CE36: =IFERROR(RATE(4,,BB36,-AY36),"") -> 0.026690096 | CF36: =IF(CE36>='Conviction List'!$D$6,1,"") | CG36: =IF(M36<='Conviction List'!$E$6,1,"") -> 1 | CH36: =IF(BG36>='Conviction List'!$F$6,1,"") -> 1 | CI36: =IF(BK36>='Conviction List'!$G$6,1,"") -> 1 | CJ36: =SUM(CF36:CI36) -> 3 | CK36: =MATCH($D36,INDIRECT($C$90&"!$C$1:$C$164"),0) -> 38
B37: =B36+1 -> 35 | C37: Krishna Defence & Allied Industries | D37: KRISHNDF | E37: KRISHNADEF | F37: =_xlfn.XLOOKUP(CCA_Defense!$D37,BB_Input!$C$4:$C$172,BB_Input!$G$4:$G$172) -> 130.14987 | G37: 2007 | H37: =YEAR(TODAY())-G37 -> 19 | I37: Listed | J37: Field kitchens | L37: Yes | M37: 57 | N37: =IFERROR(_xlfn.XLOOKUP($D37,PE_Projections!$D:$D,PE_Projections!L:L),"") -> 41.345254 | O37: =IFERROR(_xlfn.XLOOKUP($D37,PE_Projections!$D:$D,PE_Projections!M:M),"") -> 27.15616 | P37: =IFERROR(_xlfn.XLOOKUP($D37,PE_Projections!$D:$D,PE_Projections!N:N),"") -> 17.836558 | Q37: =IFERROR(_xlfn.XLOOKUP($D37,PE_Projections!$D:$D,PE_Projections!O:O),"") -> 11.715309 | R37: =IFERROR(_xlfn.XLOOKUP($D37,PE_Projections!$D:$D,PE_Projections!P:P),"") -> 7.6947844 | S37: 84 | T37: =IFERROR(RATE(5,,BB37,-AY37),"") -> 0.3160171 | U37: =(40%+50%)/2 -> 0.45 | V37: 0.95 | W37: 1.1 | X37: {=_xlfn.IFS($F37<Glossary!$C$54,Glossary!$B$54,$F37<Glossary!$C$55,Glossary!$B$55,$F37>Glossary!$C$56,Glossary!$B$56)} -> Small Cap | Y37: Vadodara | Z37: Family | AA37: 0.73 | AC37: High | AD37: High | AE37: High | AF37: Operates in a Duopoly market, manufactures "life critical" niche products for Defense | AG37: Jay Chhalera family | AL37: Y | AQ37: Y | AU37: Diversified | AV37: 100.3 | AW37: 100.3 | AX37: 100.3 | AY37: 22.5 | AZ37: 12.2 | BA37: 7.2 | BB37: 5.7 | BC37: 37.59 | BG37: 0.1846 | BK37: 0.238 | CF37: =IF(CE37>='Conviction List'!$D$8,1,"") | CG37: =IF(M37<='Conviction List'!$E$8,1,"") -> 1 | CH37: =IF(BG37>='Conviction List'!$F$8,1,"") -> 1 | CI37: =IF(BK37>='Conviction List'!$G$8,1,"") | CJ37: =SUM(CF37:CI37) -> 2 | CK37: =MATCH($D37,INDIRECT($C$90&"!$C$1:$C$164"),0) -> 52
